<?xml version="1.0" encoding="utf-8"?>
<!-- This URDF was automatically created by SolidWorks to URDF Exporter! Originally created by Stephen Brawner (brawner@gmail.com) 
     Commit Version: 1.6.0-4-g7f85cfe  Build Version: 1.6.7995.38578
     For more information, please see http://wiki.ros.org/sw_urdf_exporter -->
<robot
  name="mars_rover_v8">
  <link
    name="dummy_link">
  </link>
    <joint name="dummy_joint" type="fixed">
      <parent link="dummy_link"/>
      <child link="Rover_body"/>
      <origin xyz="0 0 0" rpy="0 0 0" />
      <axis
      xyz="0 0 0" />
    </joint>
    
  <link
    name="Rover_body">
    <inertial>
      <origin
        xyz="0 0 -0.90"
        rpy="0 0 0" />
      <mass
        value="5.05463116322645" />
      <inertia
        ixx="0.00919072374274727"
        ixy="9.21619169351263E-06"
        ixz="0.000742948997031083"
        iyy="0.0124092523200571"
        iyz="6.063504394883E-05"
        izz="0.0118258433412729" />
    </inertial>
    <visual>
      <origin
        xyz="0 0 0"
        rpy="0 0 0" />
      <geometry>
        <mesh
          filename="package://mars_rover_v8/meshes/Rover_body.STL" />
      </geometry>
      <material
        name="">
        <color
          rgba="0.792156862745098 0.819607843137255 0.933333333333333 1" />
      </material>
    </visual>
    <collision>
      <origin
        xyz="0 0 0"
        rpy="0 0 0" />
      <geometry>
        <mesh
          filename="package://mars_rover_v8/meshes/Rover_body.STL" />
      </geometry>
    </collision>
  </link>
  <link
    name="Rocker_bogie">
    <inertial>
      <origin
        xyz="-0.00183062327350716 -7.69444459586266E-06 -0.00980214891887629"
        rpy="0 0 0" />
      <mass
        value="0.222835377250285" />
      <inertia
        ixx="0.000360928093195999"
        ixy="-1.12175361239904E-08"
        ixz="-1.21543020229572E-08"
        iyy="3.37038043417026E-05"
        iyz="5.2718041267806E-09"
        izz="0.000380480874024538" />
    </inertial>
    <visual>
      <origin
        xyz="0 0 0"
        rpy="0 0 0" />
      <geometry>
        <mesh
          filename="package://mars_rover_v8/meshes/Rocker_bogie.STL" />
      </geometry>
      <material
        name="">
        <color
          rgba="0.752941176470588 0.752941176470588 0.752941176470588 1" />
      </material>
    </visual>
    <collision>
      <origin
        xyz="0 0 0"
        rpy="0 0 0" />
      <geometry>
        <mesh
          filename="package://mars_rover_v8/meshes/Rocker_bogie.STL" />
      </geometry>
    </collision>
  </link>
  <joint
    name="Rocker_bogie_joint"
    type="fixed">
    <origin
      xyz="0 0 0.321745694454397"
      rpy="0 0 3.13719265835774" />
    <parent
      link="Rover_body" />
    <child
      link="Rocker_bogie" />
    <axis
      xyz="-0.00421056605326748 -0.0042462882407935 -0.999982119924995" />
    <limit
      lower="0"
      upper="0"
      effort="0"
      velocity="0" />
  </joint>
  <link
    name="RBL_connector">
    <inertial>
      <origin
        xyz="0.00273012533204613 0.051254859123566 -8.18345316958569E-05"
        rpy="0 0 0" />
      <mass
        value="0.070232461995793" />
      <inertia
        ixx="4.3726135656864E-05"
        ixy="-1.80770334367043E-07"
        ixz="7.29077461067858E-08"
        iyy="2.25741236050298E-05"
        iyz="7.41315304509806E-06"
        izz="3.25567515859379E-05" />
    </inertial>
    <visual>
      <origin
        xyz="0 0 0"
        rpy="0 0 0" />
      <geometry>
        <mesh
          filename="package://mars_rover_v8/meshes/RBL_connector.STL" />
      </geometry>
      <material
        name="">
        <color
          rgba="0.752941176470588 0.752941176470588 0.752941176470588 1" />
      </material>
    </visual>
    <collision>
      <origin
        xyz="0 0 0"
        rpy="0 0 0" />
      <geometry>
        <mesh
          filename="package://mars_rover_v8/meshes/RBL_connector.STL" />
      </geometry>
    </collision>
  </link>
  <joint
    name="RBL_connector_joint"
    type="fixed">
    <origin
      xyz="-0.0899648316067737 -0.173480451030132 -0.0104717645625004"
      rpy="-1.5707963267949 0 0.00422849637243022" />
    <parent
      link="Rocker_bogie" />
    <child
      link="RBL_connector" />
    <axis
      xyz="0 0 0" />
    <limit
      lower="0"
      upper="0"
      effort="0"
      velocity="0" />
    <dynamics damping="0.0" friction="0.0"/>

  </joint>
  <link
    name="Main_RBL_shaft">
    <inertial>
      <origin
        xyz="0.0078042426420091 0.00361719524194832 -0.0178113948108033"
        rpy="0 0 0" />
      <mass
        value="0.0491872656663331" />
      <inertia
        ixx="1.29488130430966E-05"
        ixy="3.61515022785671E-06"
        ixz="-5.30362861188594E-06"
        iyy="2.524162119039E-05"
        iyz="1.78408297953142E-06"
        izz="2.49334638894304E-05" />
    </inertial>
    <visual>
      <origin
        xyz="0 0 0"
        rpy="0 0 0" />
      <geometry>
        <mesh
          filename="package://mars_rover_v8/meshes/Main_RBL_shaft.STL" />
      </geometry>
      <material
        name="">
        <color
          rgba="0.752941176470588 0.752941176470588 0.752941176470588 1" />
      </material>
    </visual>
    <collision>
      <origin
        xyz="0 0 0"
        rpy="0 0 0" />
      <geometry>
        <mesh
          filename="package://mars_rover_v8/meshes/Main_RBL_shaft.STL" />
      </geometry>
    </collision>
  </link>
  <joint
    name="Main_RBL_shaft_joint"
    type="revolute">
    <origin
      xyz="0.000631495837738971 0.06427021565357 -0.0564721133745778"
      rpy="-2.98277640343485 -0.284969295585532 2.83906445659194" />
    <parent
      link="RBL_connector" />
    <child
      link="Main_RBL_shaft" />
    <axis
      xyz="0.331170055115093 0.0444834262870377 -0.942521946365617" />
    <limit
      lower="-0.5"
      upper="0.5"
      effort="10"
      velocity="100" />
    <dynamics damping="1.0" friction="1.0"/>

  </joint>
  <link
    name="RBL_middle">
    <inertial>
      <origin
        xyz="-0.125359927941052 0.0848748247362183 -0.0734828208580134"
        rpy="0 0 0" />
      <mass
        value="0.033279888024897" />
      <inertia
        ixx="1.30948542082596E-05"
        ixy="9.76134365773125E-06"
        ixz="-6.29292322879668E-06"
        iyy="2.20361929304674E-05"
        iyz="4.03565033308475E-06"
        izz="2.61402496675802E-05" />
    </inertial>
    <visual>
      <origin
        xyz="0 0 0"
        rpy="0 0 0" />
      <geometry>
        <mesh
          filename="package://mars_rover_v8/meshes/RBL_middle.STL" />
      </geometry>
      <material
        name="">
        <color
          rgba="0.752941176470588 0.752941176470588 0.752941176470588 1" />
      </material>
    </visual>
    <collision>
      <origin
        xyz="0 0 0"
        rpy="0 0 0" />
      <geometry>
        <mesh
          filename="package://mars_rover_v8/meshes/RBL_middle.STL" />
      </geometry>
    </collision>
  </link>
  <joint
    name="RBL_middle_joint"
    type="fixed">
    <origin
      xyz="0 0 0"
      rpy="0 0 0" />
    <parent
      link="Main_RBL_shaft" />
    <child
      link="RBL_middle" />
    <axis
      xyz="0 0 0" />
  </joint>
  <link
    name="RBL_sub">
    <inertial>
      <origin
        xyz="0.000829595906266911 0.00229485076186861 -0.0146534396629263"
        rpy="0 0 0" />
      <mass
        value="0.0384144996450757" />
      <inertia
        ixx="5.75044699429699E-06"
        ixy="3.1860938525737E-07"
        ixz="-7.31290112807747E-07"
        iyy="1.61734907438067E-05"
        iyz="-3.55938893525851E-08"
        izz="1.63701204434969E-05" />
    </inertial>
    <visual>
      <origin
        xyz="0 0 0"
        rpy="0 0 0" />
      <geometry>
        <mesh
          filename="package://mars_rover_v8/meshes/RBL_sub.STL" />
      </geometry>
      <material
        name="">
        <color
          rgba="0.752941176470588 0.752941176470588 0.752941176470588 1" />
      </material>
    </visual>
    <collision>
      <origin
        xyz="0 0 0"
        rpy="0 0 0" />
      <geometry>
        <mesh
          filename="package://mars_rover_v8/meshes/RBL_sub.STL" />
      </geometry>
    </collision>
  </link>
  <joint
    name="RBL_sub_joint"
    type="revolute">
    <origin
      xyz="-0.165228843532702 0.110053086792123 -0.0403563616500445"
      rpy="-0.141384243529562 -0.19020881267445 -0.0998429541958625" />
    <parent
      link="RBL_middle" />
    <child
      link="RBL_sub" />
    <axis
      xyz="0.107516177735359 0 -0.994203335100611" />
    <limit
      lower="-0.5"
      upper="0.5"
      effort="10"
      velocity="100" />
    <dynamics damping="1.0" friction="1.0"/>
  </joint>
  <link
    name="RBL_rear">
    <inertial>
      <origin
        xyz="-0.0345314743918841 0.0342554022657289 -0.00245860386260088"
        rpy="0 0 0" />
      <mass
        value="0.172119977743607" />
      <inertia
        ixx="8.94538481514293E-05"
        ixy="-4.65295237181543E-06"
        ixz="-2.96847292194131E-06"
        iyy="9.87966505115758E-05"
        iyz="-9.92270152291458E-06"
        izz="7.89446484933328E-05" />
    </inertial>
    <visual>
      <origin
        xyz="0 0 0"
        rpy="0 0 0" />
      <geometry>
        <mesh
          filename="package://mars_rover_v8/meshes/RBL_rear.STL" />
      </geometry>
      <material
        name="">
        <color
          rgba="0.752941176470588 0.752941176470588 0.752941176470588 1" />
      </material>
    </visual>
    <collision>
      <origin
        xyz="0 0 0"
        rpy="0 0 0" />
      <geometry>
        <mesh
          filename="package://mars_rover_v8/meshes/RBL_rear.STL" />
      </geometry>
    </collision>
  </link>
  <joint
    name="RBL_rear_joint"
    type="fixed">
    <origin
      xyz="0 0 0"
      rpy="0 0 0" />
    <parent
      link="RBL_sub" />
    <child
      link="RBL_rear" />
    <axis
      xyz="0 0 0" />
  </joint>
  <link
    name="Left_rear_wheel_shaft">
    <inertial>
      <origin
        xyz="0.0437952760701534 0.00512357289175613 0.0446637087872099"
        rpy="0 0 0" />
      <mass
        value="0.232916021206215" />
      <inertia
        ixx="7.11736613895528E-05"
        ixy="-1.39358357582043E-05"
        ixz="5.68457382014426E-06"
        iyy="0.000197577237836181"
        iyz="-1.57927192737246E-06"
        izz="0.00017873090091453" />
    </inertial>
    <visual>
      <origin
        xyz="0 0 0"
        rpy="0 0 0" />
      <geometry>
        <mesh
          filename="package://mars_rover_v8/meshes/Left_rear_wheel_shaft.STL" />
      </geometry>
      <material
        name="">
        <color
          rgba="0.752941176470588 0.752941176470588 0.752941176470588 1" />
      </material>
    </visual>
    <collision>
      <origin
        xyz="0 0 0"
        rpy="0 0 0" />
      <geometry>
        <mesh
          filename="package://mars_rover_v8/meshes/Left_rear_wheel_shaft.STL" />
      </geometry>
    </collision>
  </link>
  <joint
    name="Left_rear_wheel_shaft_joint"
    type="revolute">
    <origin
      xyz="-0.112959679328628 0.160160817370863 0.00243708982821339"
      rpy="-2.85755335150211 1.53424034262611 1.52440909514195" />
    <parent
      link="RBL_rear" />
    <child
      link="Left_rear_wheel_shaft" />
    <axis
      xyz="-0.00154474032954976 0.000395300951298722 0.999998728756428" />
    <limit
      lower="-3.14"
      upper="3.14"
      effort="10"
      velocity="100" />
    <dynamics damping="1.0" friction="1.0"/>
  </joint>
  <link
    name="Left_rear_wheel_link">
    <inertial>
      <origin
        xyz="-0.00584958116844816 0.000388674749067369 -0.0129205752485559"
        rpy="0 0 0" />
      <mass
        value="0.0072539802205253" />
      <inertia
        ixx="5.90602559393169E-07"
        ixy="-2.10411835375521E-09"
        ixz="1.34162351668438E-07"
        iyy="5.59694857906414E-07"
        iyz="1.94505089294954E-09"
        izz="8.28822298314107E-07" />
    </inertial>
    <visual>
      <origin
        xyz="0 0 0"
        rpy="0 0 0" />
      <geometry>
        <mesh
          filename="package://mars_rover_v8/meshes/Left_rear_wheel_link.STL" />
      </geometry>
      <material
        name="">
        <color
          rgba="0.752941176470588 0.752941176470588 0.752941176470588 1" />
      </material>
    </visual>
    <collision>
      <origin
        xyz="0 0 0"
        rpy="0 0 0" />
      <geometry>
        <mesh
          filename="package://mars_rover_v8/meshes/Left_rear_wheel_link.STL" />
      </geometry>
    </collision>
  </link>
  <joint
    name="Left_rear_wheel_link_joint"
    type="continuous">
    <origin
      xyz="-0.0144096961014676 -0.00161649569607947 0.000326244371409559"
      rpy="-1.54371094057743 0.0601484877717451 2.10950882986517" />
    <parent
      link="Left_rear_wheel_shaft" />
    <child
      link="Left_rear_wheel_link" />
    <axis
      xyz="-0.410145106605342 0 -0.912020280217328" />
    <dynamics damping="1.0" friction="1.0"/>
  </joint>
  <link
    name="Left_rear_wheel">
    <inertial>
      <origin
        xyz="-0.0044781509496655 6.42513947601842E-09 -0.0099578607927876"
        rpy="0 0 0" />
      <mass
        value="0.235972094522633" />
      <inertia
        ixx="0.000574232045032266"
        ixy="3.37018139429297E-11"
        ixz="0.00011407177042807"
        iyy="0.000522932805641486"
        iyz="-8.42279815094519E-13"
        izz="0.000776588731773815" />
    </inertial>
    <visual>
      <origin
        xyz="0 0 0"
        rpy="0 0 0" />
      <geometry>
        <mesh
          filename="package://mars_rover_v8/meshes/Left_rear_wheel.STL" />
      </geometry>
      <material
        name="">
        <color
          rgba="0.752941176470588 0.752941176470588 0.752941176470588 1" />
      </material>
    </visual>
    <collision>
      <origin
        xyz="0 0 0"
        rpy="0 0 0" />
      <geometry>
        <mesh
          filename="package://mars_rover_v8/meshes/Left_rear_wheel.STL" />
      </geometry>
    </collision>
  </link>
  <joint
    name="Left_rear_wheel_joint"
    type="fixed">
    <origin
      xyz="0 0 0"
      rpy="0 0 0" />
    <parent
      link="Left_rear_wheel_link" />
    <child
      link="Left_rear_wheel" />
    <axis
      xyz="-0.411509138509028 0.0928949855933232 -0.906659114869075" />
  </joint>
  <link
    name="Left_middle_wheel_link">
    <inertial>
      <origin
        xyz="0.00347256235109557 2.59484676610466E-05 -0.0137568371943125"
        rpy="0 0 0" />
      <mass
        value="0.00725398032542629" />
      <inertia
        ixx="5.75079363468744E-07"
        ixy="1.92171893951468E-09"
        ixz="-6.92492627407769E-08"
        iyy="5.30189025822424E-07"
        iyz="4.91762571385802E-10"
        izz="8.73851342263137E-07" />
    </inertial>
    <visual>
      <origin
        xyz="0 0 0"
        rpy="0 0 0" />
      <geometry>
        <mesh
          filename="package://mars_rover_v8/meshes/Left_middle_wheel_link.STL" />
      </geometry>
      <material
        name="">
        <color
          rgba="0.752941176470588 0.752941176470588 0.752941176470588 1" />
      </material>
    </visual>
    <collision>
      <origin
        xyz="0 0 0"
        rpy="0 0 0" />
      <geometry>
        <mesh
          filename="package://mars_rover_v8/meshes/Left_middle_wheel_link.STL" />
      </geometry>
    </collision>
  </link>
  <joint
    name="Left_middle_wheel_link_joint"
    type="continuous">
    <origin
      xyz="0.143199801783518 0.0680598690493687 0.078853381971787"
      rpy="-0.110387706400515 0.220285443130636 1.5631659884914" />
    <parent
      link="RBL_rear" />
    <child
      link="Left_middle_wheel_link" />
    <axis
      xyz="0.218042111265835 0 -0.975939361699659" />
      <dynamics damping="1.0" friction="1.0"/>
  </joint>
  <link
    name="Left_middle_wheel">
    <inertial>
      <origin
        xyz="0.00261044670814156 4.15893847138804E-10 -0.0116841545180436"
        rpy="0 0 0" />
      <mass
        value="0.235972141070155" />
      <inertia
        ixx="0.000537431116155082"
        ixy="3.72109002546575E-12"
        ixz="-6.48932245240862E-05"
        iyy="0.000522932822144623"
        iyz="-1.67509429399327E-11"
        izz="0.000813389793857983" />
    </inertial>
    <visual>
      <origin
        xyz="0 0 0"
        rpy="0 0 0" />
      <geometry>
        <mesh
          filename="package://mars_rover_v8/meshes/Left_middle_wheel.STL" />
      </geometry>
      <material
        name="">
        <color
          rgba="0.752941176470588 0.752941176470588 0.752941176470588 1" />
      </material>
    </visual>
    <collision>
      <origin
        xyz="0 0 0"
        rpy="0 0 0" />
      <geometry>
        <mesh
          filename="package://mars_rover_v8/meshes/Left_middle_wheel.STL" />
      </geometry>
    </collision>
  </link>
  <joint
    name="Left_middle_wheel_joint"
    type="fixed">
    <origin
      xyz="0 0 0"
      rpy="0 0 0" />
    <parent
      link="Left_middle_wheel_link" />
    <child
      link="Left_middle_wheel" />
    <axis
      xyz="0.103888489960283 0.0205488022924037 -0.994376653174299" />
  </joint>
  <link
    name="Left_front_link">
    <inertial>
      <origin
        xyz="-0.00175656140653693 -0.140329784543421 -0.0262448368641963"
        rpy="0 0 0" />
      <mass
        value="0.107547820775352" />
      <inertia
        ixx="4.63905279506279E-05"
        ixy="-9.07830832911906E-06"
        ixz="-1.2589659345672E-05"
        iyy="7.51764610312687E-05"
        iyz="-3.74027287491525E-06"
        izz="5.97872272644151E-05" />
    </inertial>
    <visual>
      <origin
        xyz="0 0 0"
        rpy="0 0 0" />
      <geometry>
        <mesh
          filename="package://mars_rover_v8/meshes/Left_front_link.STL" />
      </geometry>
      <material
        name="">
        <color
          rgba="1 1 1 1" />
      </material>
    </visual>
    <collision>
      <origin
        xyz="0 0 0"
        rpy="0 0 0" />
      <geometry>
        <mesh
          filename="package://mars_rover_v8/meshes/Left_front_link.STL" />
      </geometry>
    </collision>
  </link>
  <joint
    name="Left_front_link_joint"
    type="fixed">
    <origin
      xyz="0.246564697808601 0.121557473831028 0.108252293859328"
      rpy="-0.0688820578620627 -0.143142944769509 -0.332117286257748" />
    <parent
      link="Main_RBL_shaft" />
    <child
      link="Left_front_link" />
    <axis
      xyz="0 0 0" />
  </joint>
  <link
    name="Left_front_wheel_shaft">
    <inertial>
      <origin
        xyz="-0.0228698033510061 0.0377008290779833 0.0442779799270307"
        rpy="0 0 0" />
      <mass
        value="0.232915997961362" />
      <inertia
        ixx="0.000165888065732098"
        ixy="5.65299105096904E-05"
        ixz="-8.91170916333238E-07"
        iyy="0.000102862867764715"
        iyz="5.83217709031911E-06"
        izz="0.000178730942674499" />
    </inertial>
    <visual>
      <origin
        xyz="0 0 0"
        rpy="0 0 0" />
      <geometry>
        <mesh
          filename="package://mars_rover_v8/meshes/Left_front_wheel_shaft.STL" />
      </geometry>
      <material
        name="">
        <color
          rgba="0.752941176470588 0.752941176470588 0.752941176470588 1" />
      </material>
    </visual>
    <collision>
      <origin
        xyz="0 0 0"
        rpy="0 0 0" />
      <geometry>
        <mesh
          filename="package://mars_rover_v8/meshes/Left_front_wheel_shaft.STL" />
      </geometry>
    </collision>
  </link>
  <joint
    name="Left_front_wheel_shaft_joint"
    type="revolute">
    <origin
      xyz="0.00262204423983718 -7.83655325365673E-05 -0.0142645567161963"
      rpy="-1.55827009941622 -0.334299120727183 -3.0884470200334" />
    <parent
      link="Left_front_link" />
    <child
      link="Left_front_wheel_shaft" />
    <axis
      xyz="-0.0551965244056398 0.0996079738083047 -0.993494637754699" />
    <limit
      lower="-3.14"
      upper="3.14"
      effort="10"
      velocity="100" />
      <dynamics damping="1.0" friction="1.0"/>
  </joint>
  <link
    name="Left_front_wheel_link">
    <inertial>
      <origin
        xyz="0.00250079430203548 -9.25893665885413E-05 -0.0139659366798912"
        rpy="0 0 0" />
      <mass
        value="0.00725398030529702" />
      <inertia
        ixx="5.72181989662649E-07"
        ixy="6.78890349983421E-09"
        ixz="-6.64271726213597E-08"
        iyy="5.31738863111652E-07"
        iyz="1.18216696117883E-09"
        izz="8.75198875704422E-07" />
    </inertial>
    <visual>
      <origin
        xyz="0 0 0"
        rpy="0 0 0" />
      <geometry>
        <mesh
          filename="package://mars_rover_v8/meshes/Left_front_wheel_link.STL" />
      </geometry>
      <material
        name="">
        <color
          rgba="0.752941176470588 0.752941176470588 0.752941176470588 1" />
      </material>
    </visual>
    <collision>
      <origin
        xyz="0 0 0"
        rpy="0 0 0" />
      <geometry>
        <mesh
          filename="package://mars_rover_v8/meshes/Left_front_wheel_link.STL" />
      </geometry>
    </collision>
  </link>
  <joint
    name="Left_front_wheel_link_joint"
    type="continuous">
    <origin
      xyz="0.00714976306738319 -0.0126188821024417 -5.94813154971563E-05"
      rpy="-1.55894415844467 -0.0572517577783187 -2.80794743393094" />
    <parent
      link="Left_front_wheel_shaft" />
    <child
      link="Left_front_wheel_link" />
    <axis
      xyz="-0.202503045698744 0 0.979281632873165" />
      <dynamics damping="1.0" friction="1.0"/>
  </joint>
  <link
    name="Front_left_wheel">
    <inertial>
      <origin
        xyz="0.00221101511168999 1.71860795039613E-09 -0.0106922512814903"
        rpy="0 0 0" />
      <mass
        value="0.235972098049911" />
      <inertia
        ixx="0.00053543825652921"
        ixy="-2.7072559146725E-11"
        ixz="-6.04748986525555E-05"
        iyy="0.000522932761528528"
        iyz="2.27456544801512E-11"
        izz="0.000815382576606525" />
    </inertial>
    <visual>
      <origin
        xyz="0 0 0"
        rpy="0 0 0" />
      <geometry>
        <mesh
          filename="package://mars_rover_v8/meshes/Front_left_wheel.STL" />
      </geometry>
      <material
        name="">
        <color
          rgba="0.250980392156863 0.250980392156863 0.250980392156863 1" />
      </material>
    </visual>
    <collision>
      <origin
        xyz="0 0 0"
        rpy="0 0 0" />
      <geometry>
        <mesh
          filename="package://mars_rover_v8/meshes/Front_left_wheel.STL" />
      </geometry>
    </collision>
  </link>
  <joint
    name="Front_left_wheel_joint"
    type="continuous">
    <origin
      xyz="0 0 0"
      rpy="0 0 0" />
    <parent
      link="Left_front_wheel_link" />
    <child
      link="Front_left_wheel" />
    <axis
      xyz="-0.202503045698744 0 0.979281632873165" />
      <dynamics damping="1.0" friction="1.0"/>
  </joint>
  <link
    name="RBR_connector">
    <inertial>
      <origin
        xyz="-0.00171976347874956 -0.0512548409233914 8.18345303948004E-05"
        rpy="0 0 0" />
      <mass
        value="0.070232461992048" />
      <inertia
        ixx="4.37261206301782E-05"
        ixy="2.51057638927394E-07"
        ixz="-7.31659856716201E-08"
        iyy="2.2574138627714E-05"
        iyz="7.41315049867749E-06"
        izz="3.25567515865713E-05" />
    </inertial>
    <visual>
      <origin
        xyz="0 0 0"
        rpy="0 0 0" />
      <geometry>
        <mesh
          filename="package://mars_rover_v8/meshes/RBR_connector.STL" />
      </geometry>
      <material
        name="">
        <color
          rgba="0.752941176470588 0.752941176470588 0.752941176470588 1" />
      </material>
    </visual>
    <collision>
      <origin
        xyz="0 0 0"
        rpy="0 0 0" />
      <geometry>
        <mesh
          filename="package://mars_rover_v8/meshes/RBR_connector.STL" />
      </geometry>
    </collision>
  </link>
  <joint
    name="RBR_connector_joint"
    type="fixed">
    <origin
      xyz="-0.0900310861478853 0.172719334408548 -0.0104717889049047"
      rpy="1.5707963267949 0 -3.13736415721736" />
    <parent
      link="Rocker_bogie" />
    <child
      link="RBR_connector" />
    <axis
      xyz="-1 0 0" />
    <limit
      lower="0"
      upper="0"
      effort="0"
      velocity="0" />
  </joint>
  <link
    name="Main_RBR_shaft">
    <inertial>
      <origin
        xyz="0.000786645565822523 -0.00390746187210316 -0.0193738562098772"
        rpy="0 0 0" />
      <mass
        value="0.0491870864909299" />
      <inertia
        ixx="9.92346891837181E-06"
        ixy="-3.32251696613761E-07"
        ixz="-6.75024917812992E-07"
        iyy="2.62769949628881E-05"
        iyz="-3.82707267467082E-07"
        izz="2.69230979903657E-05" />
    </inertial>
    <visual>
      <origin
        xyz="0 0 0"
        rpy="0 0 0" />
      <geometry>
        <mesh
          filename="package://mars_rover_v8/meshes/Main_RBR_shaft.STL" />
      </geometry>
      <material
        name="">
        <color
          rgba="0.752941176470588 0.752941176470588 0.752941176470588 1" />
      </material>
    </visual>
    <collision>
      <origin
        xyz="0 0 0"
        rpy="0 0 0" />
      <geometry>
        <mesh
          filename="package://mars_rover_v8/meshes/Main_RBR_shaft.STL" />
      </geometry>
    </collision>
  </link>
  <joint
    name="Main_RBR_shaft_joint"
    type="revolute">
    <origin
      xyz="0.000633734589216381 -0.0642701936174142 0.0564721133745718"
      rpy="-0.157071933469012 -0.00156166850799278 0" />
    <parent
      link="RBR_connector" />
    <child
      link="Main_RBR_shaft" />
    <axis
      xyz="0.000457717093941799 -0.0458478796768476 -0.998948328205318" />
    <limit
      lower="-0.5"
      upper="0.5"
      effort="10"
      velocity="100" />
      <dynamics damping="1.0" friction="1.0"/>
  </joint>
  <link
    name="RBR_middle">
    <inertial>
      <origin
        xyz="-0.158154054003957 -0.0494378401826055 -0.0293556832533867"
        rpy="0 0 0" />
      <mass
        value="0.0332798793987496" />
      <inertia
        ixx="6.46145810937674E-06"
        ixy="-6.81461547453227E-06"
        ixz="-1.16241480351458E-06"
        iyy="2.61876152303456E-05"
        iyz="-4.30336319354038E-07"
        izz="2.86222240632676E-05" />
    </inertial>
    <visual>
      <origin
        xyz="0 0 0"
        rpy="0 0 0" />
      <geometry>
        <mesh
          filename="package://mars_rover_v8/meshes/RBR_middle.STL" />
      </geometry>
      <material
        name="">
        <color
          rgba="0.752941176470588 0.752941176470588 0.752941176470588 1" />
      </material>
    </visual>
    <collision>
      <origin
        xyz="0 0 0"
        rpy="0 0 0" />
      <geometry>
        <mesh
          filename="package://mars_rover_v8/meshes/RBR_middle.STL" />
      </geometry>
    </collision>
  </link>
  <joint
    name="RBR_middle_joint"
    type="fixed">
    <origin
      xyz="0 0 0"
      rpy="0 0 0" />
    <parent
      link="Main_RBR_shaft" />
    <child
      link="RBR_middle" />
    <axis
      xyz="0 0 0" />
  </joint>
  <link
    name="RBR_sub">
    <inertial>
      <origin
        xyz="-0.00146325307394751 -0.0019204561060132 -0.0146578252316874"
        rpy="0 0 0" />
      <mass
        value="0.0384144024848232" />
      <inertia
        ixx="6.65259541744945E-06"
        ixy="3.00129204254346E-06"
        ixz="4.20442579071414E-07"
        iyy="1.52376827029145E-05"
        iyz="-7.2587115245942E-08"
        izz="1.6403442466156E-05" />
    </inertial>
    <visual>
      <origin
        xyz="0 0 0"
        rpy="0 0 0" />
      <geometry>
        <mesh
          filename="package://mars_rover_v8/meshes/RBR_sub.STL" />
      </geometry>
      <material
        name="">
        <color
          rgba="0.752941176470588 0.752941176470588 0.752941176470588 1" />
      </material>
    </visual>
    <collision>
      <origin
        xyz="0 0 0"
        rpy="0 0 0" />
      <geometry>
        <mesh
          filename="package://mars_rover_v8/meshes/RBR_sub.STL" />
      </geometry>
    </collision>
  </link>
  <joint
    name="RBR_sub_joint"
    type="revolute">
    <origin
      xyz="-0.190393496940149 -0.0676145078429574 0.0148149662588535"
      rpy="0.174524609695767 0.00171243177333767 0.00027120930134448" />
    <parent
      link="RBR_middle" />
    <child
      link="RBR_sub" />
    <axis
      xyz="0 0 -1" />
    <limit
      lower="-0.5"
      upper="0.5"
      effort="10"
      velocity="100" />
      <dynamics damping="1.0" friction="1.0"/>
  </joint>
  <link
    name="RBR_rear">
    <inertial>
      <origin
        xyz="-0.043934250888635 -0.0209782126581387 0.00126848328862761"
        rpy="0 0 0" />
      <mass
        value="0.172119885261173" />
      <inertia
        ixx="9.3324134405557E-05"
        ixy="7.59793098559351E-06"
        ixz="-7.21006336890522E-07"
        iyy="9.41705230047497E-05"
        iyz="1.01671212396701E-05"
        izz="7.97009711834079E-05" />
    </inertial>
    <visual>
      <origin
        xyz="0 0 0"
        rpy="0 0 0" />
      <geometry>
        <mesh
          filename="package://mars_rover_v8/meshes/RBR_rear.STL" />
      </geometry>
      <material
        name="">
        <color
          rgba="0.752941176470588 0.752941176470588 0.752941176470588 1" />
      </material>
    </visual>
    <collision>
      <origin
        xyz="0 0 0"
        rpy="0 0 0" />
      <geometry>
        <mesh
          filename="package://mars_rover_v8/meshes/RBR_rear.STL" />
      </geometry>
    </collision>
  </link>
  <joint
    name="RBR_rear_joint"
    type="fixed">
    <origin
      xyz="0 0 0"
      rpy="0 0 0" />
    <parent
      link="RBR_sub" />
    <child
      link="RBR_rear" />
    <axis
      xyz="0 0 0" />
  </joint>
  <link
    name="Right_rear_wheel_shaft">
    <inertial>
      <origin
        xyz="0.00704810351248669 0.0383856901852086 -0.0245611021158271"
        rpy="0 0 0" />
      <mass
        value="0.147555875096122" />
      <inertia
        ixx="0.000171589714854059"
        ixy="-2.22150838100691E-05"
        ixz="3.19923664926742E-06"
        iyy="5.96147654256339E-05"
        iyz="5.11619059142302E-06"
        izz="0.000155516697744986" />
    </inertial>
    <visual>
      <origin
        xyz="0 0 0"
        rpy="0 0 0" />
      <geometry>
        <mesh
          filename="package://mars_rover_v8/meshes/Right_rear_wheel_shaft.STL" />
      </geometry>
      <material
        name="">
        <color
          rgba="0.752941176470588 0.752941176470588 0.752941176470588 1" />
      </material>
    </visual>
    <collision>
      <origin
        xyz="0 0 0"
        rpy="0 0 0" />
      <geometry>
        <mesh
          filename="package://mars_rover_v8/meshes/Right_rear_wheel_shaft.STL" />
      </geometry>
    </collision>
  </link>
  <joint
    name="Right_rear_wheel_shaft_joint"
    type="revolute">
    <origin
      xyz="-0.158154681536852 -0.0235464270933015 0.0147039514526838"
      rpy="-1.5707963267949 0.146942207377435 -0.00258338421159216" />
    <parent
      link="RBR_rear" />
    <child
      link="Right_rear_wheel_shaft" />
    <axis
      xyz="0.00223458810126399 -0.00192570665133971 0.99999564912549" />
    <limit
      lower="-3.14"
      upper="3.14"
      effort="10"
      velocity="100" />
      <dynamics damping="1.0" friction="1.0"/>
  </joint>
  <link
    name="Right_rear_wheel_link">
    <inertial>
      <origin
        xyz="-0.00621445495246031 0.000263189120590229 0.0127523022755622"
        rpy="0 0 0" />
      <mass
        value="0.00725398032542629" />
      <inertia
        ixx="6.06221775061693E-07"
        ixy="-1.32488444793784E-08"
        ixz="-1.30141778397147E-07"
        iyy="5.43646809808467E-07"
        iyz="-6.80620430445783E-09"
        izz="8.29251146684146E-07" />
    </inertial>
    <visual>
      <origin
        xyz="0 0 0"
        rpy="0 0 0" />
      <geometry>
        <mesh
          filename="package://mars_rover_v8/meshes/Right_rear_wheel_link.STL" />
      </geometry>
      <material
        name="">
        <color
          rgba="0.752941176470588 0.752941176470588 0.752941176470588 1" />
      </material>
    </visual>
    <collision>
      <origin
        xyz="0 0 0"
        rpy="0 0 0" />
      <geometry>
        <mesh
          filename="package://mars_rover_v8/meshes/Right_rear_wheel_link.STL" />
      </geometry>
    </collision>
  </link>
  <joint
    name="Right_rear_wheel_link_joint"
    type="continuous">
    <origin
      xyz="-0.00259410496842999 -0.0141284951008775 -0.0905524791148715"
      rpy="-1.54745473961956 -0.0504296874243997 -0.615312585882" />
    <parent
      link="Right_rear_wheel_shaft" />
    <child
      link="Right_rear_wheel_link" />
    <axis
      xyz="0.419717436335965 0 -0.907654820752672" />
      <dynamics damping="1.0" friction="1.0"/>
  </joint>
  <link
    name="Right_rear_wheel">
    <inertial>
      <origin
        xyz="-0.0108083722023711 -0.0018316832855642 0.0236162690495171"
        rpy="0 0 0" />
      <mass
        value="0.32133221581393" />
      <inertia
        ixx="0.00059833966268666"
        ixy="-5.83449461960612E-08"
        ixz="-0.000112762084010149"
        iyy="0.00054614713645612"
        iyz="1.32176559338226E-07"
        izz="0.000790027489395397" />
    </inertial>
    <visual>
      <origin
        xyz="0 0 0"
        rpy="0 0 0" />
      <geometry>
        <mesh
          filename="package://mars_rover_v8/meshes/Right_rear_wheel.STL" />
      </geometry>
      <material
        name="">
        <color
          rgba="0.250980392156863 0.250980392156863 0.250980392156863 1" />
      </material>
    </visual>
    <collision>
      <origin
        xyz="0 0 0"
        rpy="0 0 0" />
      <geometry>
        <mesh
          filename="package://mars_rover_v8/meshes/Right_rear_wheel.STL" />
      </geometry>
    </collision>
  </link>
  <joint
    name="Right_rear_wheel_joint"
    type="fixed">
    <origin
      xyz="0 0 0"
      rpy="0 0 0" />
    <parent
      link="Right_rear_wheel_link" />
    <child
      link="Right_rear_wheel" />
    <axis
      xyz="0.418717449752143 0.0241629946177998 -0.907795046783227" />
  </joint>
  <link
    name="Right_middle_wheel_link">
    <inertial>
      <origin
        xyz="-0.00551284862786541 0.00014834795610405 0.0130727359449669"
        rpy="0 0 0" />
      <mass
        value="0.00725398032542629" />
      <inertia
        ixx="6.12839289693629E-07"
        ixy="9.7174482405787E-09"
        ixz="-1.25727752871587E-07"
        iyy="5.34374382020666E-07"
        iyz="4.01094615690191E-09"
        izz="8.31906059840013E-07" />
    </inertial>
    <visual>
      <origin
        xyz="0 0 0"
        rpy="0 0 0" />
      <geometry>
        <mesh
          filename="package://mars_rover_v8/meshes/Right_middle_wheel_link.STL" />
      </geometry>
      <material
        name="">
        <color
          rgba="0.752941176470588 0.752941176470588 0.752941176470588 1" />
      </material>
    </visual>
    <collision>
      <origin
        xyz="0 0 0"
        rpy="0 0 0" />
      <geometry>
        <mesh
          filename="package://mars_rover_v8/meshes/Right_middle_wheel_link.STL" />
      </geometry>
    </collision>
  </link>
  <joint
    name="Right_middle_wheel_link_joint"
    type="continuous">
    <origin
      xyz="0.120088581134656 -0.113867982924366 0.0630000000000001"
      rpy="3.14159265358979 -0.424525520533463 0.00640960722184122" />
    <parent
      link="RBR_rear" />
    <child
      link="Right_middle_wheel_link" />
    <axis
      xyz="0.411888466175252 0 -0.911234268139537" />
      <dynamics damping="1.0" friction="1.0"/>
  </joint>
  <link
    name="Rear_middle_wheel">
    <inertial>
      <origin
        xyz="-0.00484227143054637 -3.25469512452159E-11 0.0107127158315934"
        rpy="0 0 0" />
      <mass
        value="0.235972140997582" />
      <inertia
        ixx="0.000574669113951944"
        ixy="1.38048742418621E-12"
        ixz="-0.000114457898733194"
        iyy="0.000522932822727717"
        iyz="-3.01519635815039E-12"
        izz="0.000776151796329168" />
    </inertial>
    <visual>
      <origin
        xyz="0 0 0"
        rpy="0 0 0" />
      <geometry>
        <mesh
          filename="package://mars_rover_v8/meshes/Rear_middle_wheel.STL" />
      </geometry>
      <material
        name="">
        <color
          rgba="0.752941176470588 0.752941176470588 0.752941176470588 1" />
      </material>
    </visual>
    <collision>
      <origin
        xyz="0 0 0"
        rpy="0 0 0" />
      <geometry>
        <mesh
          filename="package://mars_rover_v8/meshes/Rear_middle_wheel.STL" />
      </geometry>
    </collision>
  </link>
  <joint
    name="Rear_middle_wheel_joint"
    type="fixed">
    <origin
      xyz="0 0 0"
      rpy="0 0 0" />
    <parent
      link="Right_middle_wheel_link" />
    <child
      link="Rear_middle_wheel" />
    <axis
      xyz="0.411863092610241 -0.018801914266427 -0.91105174439515" />
  </joint>
  <link
    name="RBR_front_link">
    <inertial>
      <origin
        xyz="0.209965064361985 -0.0478417179721644 0.019612021876041"
        rpy="0 0 0" />
      <mass
        value="0.0740403743388685" />
      <inertia
        ixx="3.18548188637426E-05"
        ixy="8.77708436539547E-06"
        ixz="-8.13375964177381E-06"
        iyy="6.97692683566078E-05"
        iyz="3.41765459554196E-06"
        izz="5.88285799800042E-05" />
    </inertial>
    <visual>
      <origin
        xyz="0 0 0"
        rpy="0 0 0" />
      <geometry>
        <mesh
          filename="package://mars_rover_v8/meshes/RBR_front_link.STL" />
      </geometry>
      <material
        name="">
        <color
          rgba="1 1 1 1" />
      </material>
    </visual>
    <collision>
      <origin
        xyz="0 0 0"
        rpy="0 0 0" />
      <geometry>
        <mesh
          filename="package://mars_rover_v8/meshes/RBR_front_link.STL" />
      </geometry>
    </collision>
  </link>
  <joint
    name="RBR_front_linkt_joint"
    type="fixed">
    <origin
      xyz="0 0 0"
      rpy="0 0 0" />
    <parent
      link="Main_RBR_shaft" />
    <child
      link="RBR_front_link" />
    <axis
      xyz="0 0 0" />
  </joint>
  <link
    name="Right_front_wheel_shaft">
    <inertial>
      <origin
        xyz="-0.022448496804478 0.0381089455750167 -0.0462150170605818"
        rpy="0 0 0" />
      <mass
        value="0.232915994994577" />
      <inertia
        ixx="0.000166514722719473"
        ixy="5.61760003454675E-05"
        ixz="-8.58732454008304E-07"
        iyy="0.000102236207341924"
        iyz="5.8370438102259E-06"
        izz="0.000178730933725245" />
    </inertial>
    <visual>
      <origin
        xyz="0 0 0"
        rpy="0 0 0" />
      <geometry>
        <mesh
          filename="package://mars_rover_v8/meshes/Right_front_wheel_shaft.STL" />
      </geometry>
      <material
        name="">
        <color
          rgba="0.752941176470588 0.752941176470588 0.752941176470588 1" />
      </material>
    </visual>
    <collision>
      <origin
        xyz="0 0 0"
        rpy="0 0 0" />
      <geometry>
        <mesh
          filename="package://mars_rover_v8/meshes/Right_front_wheel_shaft.STL" />
      </geometry>
    </collision>
  </link>
  <joint
    name="Right_front_wheel_shaft_joint"
    type="revolute">
    <origin
      xyz="0.232033150163403 -0.088963153619722 0.0249628677160633"
      rpy="-1.37097490593956 -0.505717767944392 -0.0878138371783758" />
    <parent
      link="RBR_front_link" />
    <child
      link="Right_front_wheel_shaft" />
    <axis
      xyz="-0.00294985923430682 0 -0.99999564912549" />
    <limit
      lower="-3.14"
      upper="3.14"
      effort="10"
      velocity="100" />
      <dynamics damping="1.0" friction="1.0"/>
  </joint>
  <link
    name="Right_front_wheel_link">
    <inertial>
      <origin
        xyz="0.00254753967073165 -0.000309236482963202 -0.0139543665789996"
        rpy="0 0 0" />
      <mass
        value="0.00725398032542629" />
      <inertia
        ixx="5.54775023795211E-07"
        ixy="1.43092528498364E-08"
        ixz="-6.74153169038239E-08"
        iyy="5.48818108086666E-07"
        iyz="2.12218616478764E-09"
        izz="8.75526599672433E-07" />
    </inertial>
    <visual>
      <origin
        xyz="0 0 0"
        rpy="0 0 0" />
      <geometry>
        <mesh
          filename="package://mars_rover_v8/meshes/Right_front_wheel_link.STL" />
      </geometry>
      <material
        name="">
        <color
          rgba="0.752941176470588 0.752941176470588 0.752941176470588 1" />
      </material>
    </visual>
    <collision>
      <origin
        xyz="0 0 0"
        rpy="0 0 0" />
      <geometry>
        <mesh
          filename="package://mars_rover_v8/meshes/Right_front_wheel_link.STL" />
      </geometry>
    </collision>
  </link>
  <joint
    name="Right_front_wheel_link_joint"
    type="continuous">
    <origin
      xyz="0.00729082919570312 -0.0123768963816303 -0.0905524791148777"
      rpy="1.59422824475325 0.116637230630436 0.731068414853812" />
    <parent
      link="Right_front_wheel_shaft" />
    <child
      link="Right_front_wheel_link" />
    <axis
      xyz="0.196083662831013 0 -0.980587169593185" />
      <dynamics damping="1.0" friction="1.0"/>
  </joint>
  <link
    name="Right_front_wheel">
    <inertial>
      <origin
        xyz="0.00214093203857663 7.28689983353625E-10 -0.0107065035797874"
        rpy="0 0 0" />
      <mass
        value="0.235972140918487" />
      <inertia
        ixx="0.000534657991546226"
        ixy="5.05623723499968E-12"
        ixz="-5.86359297742129E-05"
        iyy="0.000522932823110295"
        iyz="-2.54580047618296E-11"
        izz="0.000816162919032008" />
    </inertial>
    <visual>
      <origin
        xyz="0 0 0"
        rpy="0 0 0" />
      <geometry>
        <mesh
          filename="package://mars_rover_v8/meshes/Right_front_wheel.STL" />
      </geometry>
      <material
        name="">
        <color
          rgba="0.752941176470588 0.752941176470588 0.752941176470588 1" />
      </material>
    </visual>
    <collision>
      <origin
        xyz="0 0 0"
        rpy="0 0 0" />
      <geometry>
        <mesh
          filename="package://mars_rover_v8/meshes/Right_front_wheel.STL" />
      </geometry>
    </collision>
  </link>
  <joint
    name="Right_front_wheel_joint"
    type="fixed">
    <origin
      xyz="0 0 0"
      rpy="0 0 0" />
    <parent
      link="Right_front_wheel_link" />
    <child
      link="Right_front_wheel" />
    <axis
      xyz="-0.573374677283095 -0.138797386351894 0.807450781777063" />
  </joint>
  <link
    name="Arm_base">
    <inertial>
      <origin
        xyz="-0.0148411799642182 0.00513979068023006 0.00849233477254038"
        rpy="0 0 0" />
      <mass
        value="0.0232103582364868" />
      <inertia
        ixx="1.95534334339789E-05"
        ixy="5.5258265426851E-08"
        ixz="5.40978258405581E-09"
        iyy="1.9473715923075E-05"
        iyz="-1.08581050378252E-08"
        izz="1.34195686136076E-05" />
    </inertial>
    <visual>
      <origin
        xyz="0 0 0"
        rpy="0 0 0" />
      <geometry>
        <mesh
          filename="package://mars_rover_v8/meshes/Arm_base.STL" />
      </geometry>
      <material
        name="">
        <color
          rgba="0.792156862745098 0.819607843137255 0.933333333333333 1" />
      </material>
    </visual>
    <collision>
      <origin
        xyz="0 0 0"
        rpy="0 0 0" />
      <geometry>
        <mesh
          filename="package://mars_rover_v8/meshes/Arm_base.STL" />
      </geometry>
    </collision>
  </link>
  <joint
    name="Arm_base_joint"
    type="revolute">
    <origin
      xyz="0.246564015739666 -0.00508471654694997 0.346052237901634"
      rpy="0 0 -0.000171498859619441" />
    <parent
      link="Rover_body" />
    <child
      link="Arm_base" />
    <axis
      xyz="0 0 1" />
    <limit
      lower="-1.25"
      upper="0.25"
      effort="10"
      velocity="1000" />
      <dynamics damping="1.0" friction="1.0"/>
  </joint>
  <link
    name="Arm_base2">
    <inertial>
      <origin
        xyz="-0.0150559555045656 0.00504243102485956 0.0465115492607505"
        rpy="0 0 0" />
      <mass
        value="0.0831040109788547" />
      <inertia
        ixx="4.60526006657726E-05"
        ixy="8.35430769810964E-21"
        ixz="7.17059146252918E-21"
        iyy="4.60526006657725E-05"
        iyz="2.63039153409463E-21"
        izz="6.95090782864064E-05" />
    </inertial>
    <visual>
      <origin
        xyz="0 0 0"
        rpy="0 0 0" />
      <geometry>
        <mesh
          filename="package://mars_rover_v8/meshes/Arm_base2.STL" />
      </geometry>
      <material
        name="">
        <color
          rgba="1 1 1 1" />
      </material>
    </visual>
    <collision>
      <origin
        xyz="0 0 0"
        rpy="0 0 0" />
      <geometry>
        <mesh
          filename="package://mars_rover_v8/meshes/Arm_base2.STL" />
      </geometry>
    </collision>
  </link>
  <joint
    name="Arm_base2_joint"
    type="fixed">
    <origin
      xyz="0 0 0"
      rpy="0 0 0" />
    <parent
      link="Arm_base" />
    <child
      link="Arm_base2" />
    <axis
      xyz="0 0 0" />
  </joint>
  <link
    name="Arm_link1">
    <inertial>
      <origin
        xyz="-0.000198870707785098 2.17764732455689E-05 0.0542205046374554"
        rpy="0 0 0" />
      <mass
        value="1.17715491787185" />
      <inertia
        ixx="0.00149566117048205"
        ixy="-1.14408893577745E-05"
        ixz="-2.38607146559717E-09"
        iyy="0.00139122143440578"
        iyz="-7.70569549325806E-10"
        izz="0.000580577884164837" />
    </inertial>
    <visual>
      <origin
        xyz="0 0 0"
        rpy="0 0 0" />
      <geometry>
        <mesh
          filename="package://mars_rover_v8/meshes/Arm_link1.STL" />
      </geometry>
      <material
        name="">
        <color
          rgba="0.6 0.6 0.6 1" />
      </material>
    </visual>
    <collision>
      <origin
        xyz="0 0 0"
        rpy="0 0 0" />
      <geometry>
        <mesh
          filename="package://mars_rover_v8/meshes/Arm_link1.STL" />
      </geometry>
    </collision>
  </link>
  <joint
    name="Arm_link1_joint"
    type="fixed">
    <origin
      xyz="-0.0150560289785289 0.00504237928468466 0.111426422730127"
      rpy="0 0 1.5707963267949" />
    <parent
      link="Arm_base2" />
    <child
      link="Arm_link1" />
    <axis
      xyz="0 0 0" />
  </joint>
  <link
    name="Arm_link2">
    <inertial>
      <origin
        xyz="-0.00366205828125533 0.061988701777348 -5.84840138262432E-08"
        rpy="0 0 0" />
      <mass
        value="0.726851554166845" />
      <inertia
        ixx="0.00278764657763794"
        ixy="0.000151701020942583"
        ixz="-3.74959464464943E-10"
        iyy="0.000228387594610631"
        iyz="-1.505400866191E-10"
        izz="0.00278286795091919" />
    </inertial>
    <visual>
      <origin
        xyz="0 0 0"
        rpy="0 0 0" />
      <geometry>
        <mesh
          filename="package://mars_rover_v8/meshes/Arm_link2.STL" />
      </geometry>
      <material
        name="">
        <color
          rgba="0.6 0.6 0.6 1" />
      </material>
    </visual>
    <collision>
      <origin
        xyz="0 0 0"
        rpy="0 0 0" />
      <geometry>
        <mesh
          filename="package://mars_rover_v8/meshes/Arm_link2.STL" />
      </geometry>
    </collision>
  </link>
  <joint
    name="Arm_link2_joint"
    type="revolute">
    <origin
      xyz="0.0625642335830836 -0.00642926901750175 0.0605176899996075"
      rpy="1.5707963267949 0 1.46291321716714" />
    <parent
      link="Arm_link1" />
    <child
      link="Arm_link2" />
    <axis
      xyz="0 0 -1" />
    <limit
      lower="-2.75"
      upper="1.725"
      effort="10"
      velocity="1000" />
      <dynamics damping="1.0" friction="1.0"/>
  </joint>
  <link
    name="Arm_link3">
    <inertial>
      <origin
        xyz="0.000165500891682907 3.13668146730423E-05 -0.0066040257148271"
        rpy="0 0 0" />
      <mass
        value="0.601598112953303" />
      <inertia
        ixx="0.00116811789081315"
        ixy="5.74958844827927E-07"
        ixz="7.18396649352535E-07"
        iyy="0.00116519349842926"
        iyz="1.90506856782321E-07"
        izz="0.000409953538663675" />
    </inertial>
    <visual>
      <origin
        xyz="0 0 0"
        rpy="0 0 0" />
      <geometry>
        <mesh
          filename="package://mars_rover_v8/meshes/Arm_link3.STL" />
      </geometry>
      <material
        name="">
        <color
          rgba="0.686274509803922 0.658823529411765 0.63921568627451 1" />
      </material>
    </visual>
    <collision>
      <origin
        xyz="0 0 0"
        rpy="0 0 0" />
      <geometry>
        <mesh
          filename="package://mars_rover_v8/meshes/Arm_link3.STL" />
      </geometry>
    </collision>
  </link>
  <joint
    name="Arm_link3_joint"
    type="fixed">
    <origin
      xyz="-0.0147322442377674 0.247644449205892 -0.000340421304941302"
      rpy="-1.5707963267949 -1.46309949588283 0.0590019020044591" />
    <parent
      link="Arm_link2" />
    <child
      link="Arm_link3" />
    <axis
      xyz="-0.101366846595857 0.116708252977962 0.987979729598763" />
    <limit
      lower="0"
      upper="0"
      effort="0"
      velocity="0" />
      <dynamics damping="1.0" friction="1.0"/>
  </joint>
  <link
    name="Arm_link4">
    <inertial>
      <origin
        xyz="-3.33066907387547E-16 1.38777878078145E-17 -0.010042610343672"
        rpy="0 0 0" />
      <mass
        value="0.242640656011816" />
      <inertia
        ixx="0.000371978079333012"
        ixy="1.6940658945086E-20"
        ixz="-4.49986253228847E-21"
        iyy="0.000371978079333012"
        iyz="-2.92226366802734E-20"
        izz="9.98978057819488E-05" />
    </inertial>
    <visual>
      <origin
        xyz="0 0 0"
        rpy="0 0 0" />
      <geometry>
        <mesh
          filename="package://mars_rover_v8/meshes/Arm_link4.STL" />
      </geometry>
      <material
        name="">
        <color
          rgba="0.6 0.6 0.6 1" />
      </material>
    </visual>
    <collision>
      <origin
        xyz="0 0 0"
        rpy="0 0 0" />
      <geometry>
        <mesh
          filename="package://mars_rover_v8/meshes/Arm_link4.STL" />
      </geometry>
    </collision>
  </link>
  <joint
    name="Arm_link4_joint"
    type="prismatic">
    <origin
      xyz="0.000349494648019921 6.62403289212188E-05 0.0303927382056502"
      rpy="0 0 -0.107696830912061" />
    <parent
      link="Arm_link3" />
    <child
      link="Arm_link4" />
    <axis
      xyz="0 0 -1" />
    <limit
      lower="-0.09"
      upper="0.02"
      effort="10"
      velocity="100" />
      <dynamics damping="1.0" friction="1.0"/>
  </joint>
  <link
    name="End_effector">
    <inertial>
      <origin
        xyz="2.77555756156289E-17 1.38777878078145E-17 -0.00442500000000001"
        rpy="0 0 0" />
      <mass
        value="0.050219340315337" />
      <inertia
        ixx="2.3004946217965E-05"
        ixy="-1.52780259138544E-21"
        ixz="-2.80724420385184E-23"
        iyy="2.3004946217965E-05"
        iyz="4.2351647362715E-22"
        izz="4.53543417222887E-05" />
    </inertial>
    <visual>
      <origin
        xyz="0 0 0"
        rpy="0 0 0" />
      <geometry>
        <mesh
          filename="package://mars_rover_v8/meshes/End_effector.STL" />
      </geometry>
      <material
        name="">
        <color
          rgba="0.968627450980392 0.87843137254902 0.6 1" />
      </material>
    </visual>
    <collision>
      <origin
        xyz="0 0 0"
        rpy="0 0 0" />
      <geometry>
        <mesh
          filename="package://mars_rover_v8/meshes/End_effector.STL" />
      </geometry>
    </collision>
  </link>
  <joint
    name="End_effector_joint"
    type="continuous">
    <origin
      xyz="0 0 0.080538931549256"
      rpy="0 0 0.107696830912061" />
    <parent
      link="Arm_link4" />
    <child
      link="End_effector" />
    <axis
      xyz="0 0 1" />
      <dynamics damping="1.0" friction="1.0"/>
  </joint>
  <link
    name="Drill_tool">
    <inertial>
      <origin
        xyz="-2.53988950982276E-07 -2.89834425724889E-06 0.098106643016324"
        rpy="0 0 0" />
      <mass
        value="0.0369054673613966" />
      <inertia
        ixx="2.92110406918595E-05"
        ixy="4.93253783748112E-10"
        ixz="-7.31061448430268E-10"
        iyy="2.92152160276101E-05"
        iyz="-4.38438515383908E-10"
        izz="9.32227933750998E-07" />
    </inertial>
    <visual>
      <origin
        xyz="0 0 0"
        rpy="0 0 0" />
      <geometry>
        <mesh
          filename="package://mars_rover_v8/meshes/Drill_tool.STL" />
      </geometry>
      <material
        name="">
        <color
          rgba="0.776470588235294 0.756862745098039 0.737254901960784 1" />
      </material>
    </visual>
    <collision>
      <origin
        xyz="0 0 0"
        rpy="0 0 0" />
      <geometry>
        <mesh
          filename="package://mars_rover_v8/meshes/Drill_tool.STL" />
      </geometry>
    </collision>
  </link>
  <joint
    name="Drill_tool_joint"
    type="fixed">
    <origin
      xyz="0 0 0"
      rpy="0 0 0" />
    <parent
      link="End_effector" />
    <child
      link="Drill_tool" />
    <axis
      xyz="0 0 1" />
  </joint>

  
  <!--camera-->
  <link name='camera'>
     <visual name ='camera_visual'>
	<geometry>
	   <box size="0.005 0.025 0.025"/>
	</geometry>
     </visual>

    <inertial>
      	  <mass value="0.0001"/>
          <origin xyz="0 0 0" rpy=" 0 0 0"/>
	  <box_inertia m="0.1" x="0.005" y="0.025" z="0.025" />
          <inertia
            ixx="1e-6" ixy="0" ixz="0"
            iyy="1e-6" iyz="0"
            izz="1e-6"
          />
     </inertial>

     <collision name='collision'>
           <origin xyz="0 0 0" rpy=" 0 0 0"/> 
           <geometry>
             <box size="0.005 0.025 0.025"/>
           </geometry>
     </collision>
  </link>

<gazebo reference="camera">
    <material>Gazebo/Green</material>
</gazebo>

  <joint type="fixed" name="camera_joint">
    <origin xyz="0.260 0 0.45" rpy="0 0 -0.1"/>
    <child link="camera"/>
    <parent link="Rover_body"/>
    <axis xyz="0 0 0" rpy="0 0 0"/>
    <limit effort="10000" velocity="1000"/>
    <dynamics damping="1.0" friction="1.0"/>
  </joint>

  <gazebo reference="camera">
    <sensor type="camera" name="camera1">
      <update_rate>30.0</update_rate>
      <camera name="head">
        <horizontal_fov>1.3962634</horizontal_fov>
        <image>
          <width>800</width>
          <height>800</height>
          <format>R8G8B8</format>
        </image>
        <clip>
          <near>0.02</near>
          <far>300</far>
        </clip>
      </camera>
      <plugin name="camera_controller" filename="libgazebo_ros_camera.so">
        <alwaysOn>true</alwaysOn>
        <updateRate>0.0</updateRate>
        <cameraName>camera</cameraName>
        <imageTopicName>rgb/image_raw</imageTopicName>
        <cameraInfoTopicName>rgb/camera_info</cameraInfoTopicName>
        <frameName>camera</frameName>
        <hackBaseline>0.07</hackBaseline>
        <distortionK1>0.0</distortionK1>
        <distortionK2>0.0</distortionK2>
        <distortionK3>0.0</distortionK3>
        <distortionT1>0.0</distortionT1>
        <distortionT2>0.0</distortionT2>
      </plugin>
    </sensor>
  </gazebo>
  
  <transmission name="Main_RBL_shaft_joint_motor">
  <type>transmission_interface/SimpleTransmission</type>
  <joint name="Main_RBL_shaft_joint">
    <hardwareInterface>hardware_interface/EffortJointInterface</hardwareInterface>
  </joint>
  <actuator name="Main_RBL_shaft_joint_motor">
    <mechanicalReduction>1</mechanicalReduction>
    <hardwareInterface>hardware_interface/EffortJointInterface</hardwareInterface>
  </actuator>
  </transmission>

  <transmission name="Main_RBR_shaft_joint_motor">
  <type>transmission_interface/SimpleTransmission</type>
  <joint name="Main_RBR_shaft_joint">
    <hardwareInterface>hardware_interface/EffortJointInterface</hardwareInterface>
  </joint>
  <actuator name="Main_RBR_shaft_joint_motor">
    <mechanicalReduction>1</mechanicalReduction>
    <hardwareInterface>hardware_interface/EffortJointInterface</hardwareInterface>
  </actuator>
  </transmission>

  <transmission name="RBL_sub_joint_motor">
  <type>transmission_interface/SimpleTransmission</type>
  <joint name="RBL_sub_joint">
    <hardwareInterface>hardware_interface/EffortJointInterface</hardwareInterface>
  </joint>
  <actuator name="RBL_sub_joint_motor">
    <mechanicalReduction>1</mechanicalReduction>
    <hardwareInterface>hardware_interface/EffortJointInterface</hardwareInterface>
  </actuator>
  </transmission>


  
  <transmission name="RBR_sub_joint_motor">
  <type>transmission_interface/SimpleTransmission</type>
  <joint name="RBR_sub_joint">
    <hardwareInterface>hardware_interface/EffortJointInterface</hardwareInterface>
  </joint>
  <actuator name="RBR_sub_joint_motor">
    <mechanicalReduction>1</mechanicalReduction>
    <hardwareInterface>hardware_interface/EffortJointInterface</hardwareInterface>
  </actuator>
  </transmission>


  <transmission name="Left_rear_wheel_shaft_joint_motor">
  <type>transmission_interface/SimpleTransmission</type>
  <joint name="Left_rear_wheel_shaft_joint">
    <hardwareInterface>hardware_interface/EffortJointInterface</hardwareInterface>
  </joint>
  <actuator name="Left_rear_wheel_shaft_joint_motor">
    <mechanicalReduction>1</mechanicalReduction>
    <hardwareInterface>hardware_interface/EffortJointInterface</hardwareInterface>
  </actuator>
  </transmission>

  <transmission name="Right_rear_wheel_shaft_joint_motor">
  <type>transmission_interface/SimpleTransmission</type>
  <joint name="Right_rear_wheel_shaft_joint">
    <hardwareInterface>hardware_interface/EffortJointInterface</hardwareInterface>
  </joint>
  <actuator name="Right_rear_wheel_shaft_joint_motor">
    <mechanicalReduction>1</mechanicalReduction>
    <hardwareInterface>hardware_interface/EffortJointInterface</hardwareInterface>
  </actuator>
  </transmission>

  <transmission name="Left_front_wheel_shaft_joint_motor">
  <type>transmission_interface/SimpleTransmission</type>
  <joint name="Left_front_wheel_shaft_joint">
    <hardwareInterface>hardware_interface/EffortJointInterface</hardwareInterface>
  </joint>
  <actuator name="Left_front_wheel_shaft_joint_motor">
    <mechanicalReduction>1</mechanicalReduction>
    <hardwareInterface>hardware_interface/EffortJointInterface</hardwareInterface>
  </actuator>
  </transmission>


  <transmission name="Right_front_wheel_shaft_joint_motor">
  <type>transmission_interface/SimpleTransmission</type>
  <joint name="Right_front_wheel_shaft_joint">
    <hardwareInterface>hardware_interface/EffortJointInterface</hardwareInterface>
  </joint>
  <actuator name="Right_front_wheel_shaft_joint_motor">
    <mechanicalReduction>1</mechanicalReduction>
    <hardwareInterface>hardware_interface/EffortJointInterface</hardwareInterface>
  </actuator>
  </transmission>

  
  <transmission name="Arm_base_joint_motor">
  <type>transmission_interface/SimpleTransmission</type>
  <joint name="Arm_base_joint">
    <hardwareInterface>hardware_interface/EffortJointInterface</hardwareInterface>
  </joint>
  <actuator name="Arm_base_joint_motor">
    <mechanicalReduction>1</mechanicalReduction>
    <hardwareInterface>hardware_interface/EffortJointInterface</hardwareInterface>
  </actuator>
  </transmission>


  <transmission name="Arm_link2_joint_motor">
  <type>transmission_interface/SimpleTransmission</type>
  <joint name="Arm_link2_joint">
    <hardwareInterface>hardware_interface/EffortJointInterface</hardwareInterface>
  </joint>
  <actuator name="Arm_link2_joint_motor">
    <mechanicalReduction>1</mechanicalReduction>
    <hardwareInterface>hardware_interface/EffortJointInterface</hardwareInterface>
  </actuator>
  </transmission>

  <!-- <transmission name="Arm_link3_joint_motor">
  <type>transmission_interface/SimpleTransmission</type>
  <joint name="Arm_link3_joint">
    <hardwareInterface>hardware_interface/EffortJointInterface</hardwareInterface>
  </joint>
  <actuator name="Arm_link3_joint_motor">
    <mechanicalReduction>1</mechanicalReduction>
    <hardwareInterface>hardware_interface/EffectJointInterface</hardwareInterface>
  </actuator>
  </transmission> -->

  <transmission name="Arm_link4_joint_motor">
  <type>transmission_interface/SimpleTransmission</type>
  <joint name="Arm_link4_joint">
    <hardwareInterface>hardware_interface/EffortJointInterface</hardwareInterface>
  </joint>
  <actuator name="Arm_link4_joint_motor">
    <mechanicalReduction>1</mechanicalReduction>
    <hardwareInterface>hardware_interface/EffortJointInterface</hardwareInterface>
  </actuator>
  </transmission>

  <transmission name="End_effector_joint_motor">
  <type>transmission_interface/SimpleTransmission</type>
  <joint name="End_effector_joint">
    <hardwareInterface>hardware_interface/VelocityJointInterface</hardwareInterface>
  </joint>
  <actuator name="End_effector_joint_motor">
    <mechanicalReduction>1</mechanicalReduction>
    <hardwareInterface>hardware_interface/VelocityJointInterface</hardwareInterface>
  </actuator>
  </transmission>

  <transmission name="Left_rear_wheel_link_joint_motor">
  <type>transmission_interface/SimpleTransmission</type>
  <joint name="Left_rear_wheel_link_joint">
    <hardwareInterface>hardware_interface/VelocityJointInterface</hardwareInterface>
  </joint>
  <actuator name="Left_rear_wheel_link_joint_motor">
    <mechanicalReduction>1</mechanicalReduction>
    <hardwareInterface>hardware_interface/VelocityJointInterface</hardwareInterface>
  </actuator>
  </transmission>

  <transmission name="Left_middle_wheel_link_joint_motor">
  <type>transmission_interface/SimpleTransmission</type>
  <joint name="Left_middle_wheel_link_joint">
    <hardwareInterface>hardware_interface/VelocityJointInterface</hardwareInterface>
  </joint>
  <actuator name="Left_middle_wheel_link_joint_motor">
    <mechanicalReduction>1</mechanicalReduction>
    <hardwareInterface>hardware_interface/VelocityJointInterface</hardwareInterface>
  </actuator>
  </transmission>

  <transmission name="Left_front_wheel_link_joint_motor">
  <type>transmission_interface/SimpleTransmission</type>
  <joint name="Left_front_wheel_link_joint">
    <hardwareInterface>hardware_interface/VelocityJointInterface</hardwareInterface>
  </joint>
  <actuator name="Left_front_wheel_link_joint">
    <mechanicalReduction>1</mechanicalReduction>
    <hardwareInterface>hardware_interface/VelocityJointInterface</hardwareInterface>
  </actuator>
  </transmission>

  <transmission name="Right_rear_wheel_link_joint_motor">
  <type>transmission_interface/SimpleTransmission</type>
  <joint name="Right_rear_wheel_link_joint">
    <hardwareInterface>hardware_interface/VelocityJointInterface</hardwareInterface>
  </joint>
  <actuator name="Right_rear_wheel_link_joint_motor">
    <mechanicalReduction>1</mechanicalReduction>
    <hardwareInterface>hardware_interface/VelocityJointInterface</hardwareInterface>
  </actuator>
  </transmission>

  <transmission name="Right_front_wheel_link_joint_motor">
  <type>transmission_interface/SimpleTransmission</type>
  <joint name="Right_front_wheel_link_joint">
    <hardwareInterface>hardware_interface/VelocityJointInterface</hardwareInterface>
  </joint>
  <actuator name="Right_front_wheel_link_joint_motor">
    <mechanicalReduction>1</mechanicalReduction>
    <hardwareInterface>hardware_interface/VelocityJointInterface</hardwareInterface>
  </actuator>
  </transmission>

  <transmission name="Right_middle_wheel_link_joint_motor">
  <type>transmission_interface/SimpleTransmission</type>
  <joint name="Right_middle_wheel_link_joint">
    <hardwareInterface>hardware_interface/VelocityJointInterface</hardwareInterface>
  </joint>
  <actuator name="Right_middle_wheel_link_joint_motor">
    <mechanicalReduction>1</mechanicalReduction>
    <hardwareInterface>hardware_interface/VelocityJointInterface</hardwareInterface>
  </actuator>
  </transmission>

<!--  Gazebo plugin for control here -->
	<gazebo>
		<plugin name="gazebo_ros_control" filename="libgazebo_ros_control.so">
			<robotNamespace>/mars_rover_v8</robotNamespace>
			<robotSimType>gazebo_ros_control/DefaultRobotHWSim</robotSimType>
			<legacyModeNS>true</legacyModeNS>
		</plugin>
	</gazebo>

</robot>
